<?xml version="1.0"?>
<robot xmlns:xacro="http://wiki.ros.org/xacro">
  <xacro:macro name="arm" params="parent *origin name">

    <joint name="${name}base_joint" type="fixed">
      <parent link="${parent}"/>
      <child link="${name}base_link"/>
      <axis xyz="0 0 1" />
      <insert_block name="origin" />
    </joint>

    <link name="${name}base_link">
      <xacro:default_inertial/>
      <visual>
        <geometry>
          <mesh filename="package://robotino_description/meshes/arm/link0.stl"/>
        </geometry>
        <material name="white">
          <color rgba="1 1 1 1"/>
        </material>
        <origin rpy="0 0 0" xyz="0 0 0."/>
      </visual>
      <collision>
        <origin rpy="0 0 0" xyz="0 0 0."/>
        <geometry>
          <mesh filename="package://robotino_description/meshes/arm/link0_collision.stl"/>
        </geometry>
      </collision>
    </link>

    <joint name="${name}joint1" type="revolute">
      <parent link="${name}base_link"/>
      <child link="${name}link1"/>
      <origin xyz="0.0 0.0 0.0" rpy="0 0 0" />
      <axis xyz="0 1 0" />
      <limit upper="1.5" lower="-1.2" effort="190" velocity="30" />
    </joint>

    <link name="${name}link1">
      <xacro:default_inertial/>
      <visual>
        <geometry>
          <mesh filename="package://robotino_description/meshes/arm/link1.stl"/>
        </geometry>
        <material name="white" />
        <origin rpy="0 0 0" xyz="0 0 0"/>
      </visual>
      <collision>
        <origin rpy="0 0 0" xyz="0 0 0"/>
        <geometry>
          <mesh filename="package://robotino_description/meshes/arm/link1_collision.stl"/>
        </geometry>
      </collision>
    </link>

    <gazebo reference="${name}link1">
        <material>Gazebo/White</material>
    </gazebo>

    <joint name="${name}joint2" type="revolute">
      <parent link="${name}link1"/>
      <child link="${name}motor2"/>
      <origin xyz="0.0 0.0 0.25" rpy="0 0 0" />
      <axis xyz="0 1 0" />
      <limit upper="2.3" lower="-1.7" effort="190" velocity="30" />
    </joint>

    <link name="${name}motor2">
      <xacro:default_inertial/>
      <visual>
        <geometry>
          <box size="0 0 0" />
        </geometry>
        <material name="white" />
        <origin rpy="0 0 0" xyz="0 0.0625 0."/>
      </visual>
    </link>

    <joint name="fixed_motor2_link2" type="fixed">
      <parent link="${name}motor2"/>
      <child link="${name}link2"/>
      <origin xyz="0.0 0.098 0.027" rpy="0 0 0" />
    </joint>

    <link name="${name}link2">
      <xacro:default_inertial/>
      <visual>
        <geometry>
          <mesh filename="package://robotino_description/meshes/arm/link2.stl"/>
        </geometry>
        <material name="white" />
        <origin rpy="0 0 0" xyz="0 0 0"/>
      </visual>
      <collision>
        <origin rpy="0 0 0" xyz="0 0 0"/>
        <geometry>
          <mesh filename="package://robotino_description/meshes/arm/link2_collision.stl"/>
        </geometry>
      </collision>
    </link>

    <gazebo reference="${name}link2">
      <material>Gazebo/White</material>
    </gazebo>

    <joint name="${name}joint3" type="revolute">
      <parent link="${name}link2"/>
      <child link="${name}link3"/>
      <origin xyz="0.0 0.0 0.158" rpy="0 0 0" />
      <axis xyz="0 0 1" />
      <limit upper="1.8" lower="-1.8" effort="190" velocity="30" />
    </joint>

    <link name="${name}link3">
      <xacro:default_inertial/>
      <visual>
        <geometry>
          <mesh filename="package://robotino_description/meshes/arm/link3.stl"/>
        </geometry>
        <material name="white" />
        <origin rpy="0 0 0" xyz="0 0 0"/>
      </visual>
      <collision>
        <origin rpy="0 0 0" xyz="0 0 0"/>
        <geometry>
          <mesh filename="package://robotino_description/meshes/arm/link3_collision.stl"/>
        </geometry>
      </collision>
    </link>

    <gazebo reference="${name}link3">
      <material>Gazebo/White</material>
    </gazebo>

    <joint name="${name}joint4" type="revolute">
      <parent link="${name}link3"/>
      <child link="${name}link4"/>
      <origin xyz="0.0 -0.057 0.065" rpy="0 0 0" />
      <axis xyz="0 1 0" />
      <limit upper="1.9" lower="-1.9" effort="160" velocity="30" />
    </joint>

    <link name="${name}link4">
      <xacro:default_inertial/>
      <visual>
        <geometry>
          <mesh filename="package://robotino_description/meshes/arm/link4.stl"/>
        </geometry>
        <material name="white" />
        <origin rpy="0 0 0" xyz="0 0 0"/>
      </visual>
      <collision>
        <origin rpy="0 0 0" xyz="0 0 0"/>
        <geometry>
          <mesh filename="package://robotino_description/meshes/arm/link4_collision.stl"/>
        </geometry>
      </collision>
    </link>

    <gazebo reference="${name}link4">
      <material>Gazebo/White</material>
    </gazebo>

    <joint name="${name}joint5" type="revolute">
      <parent link="${name}link4"/>
      <child link="${name}link5"/>
      <origin xyz="0.0 -0.027 0.035" rpy="0 0 0" />
      <axis xyz="0 0 1" />
      <limit upper="2.9" lower="-2.9" effort="160" velocity="30" />
    </joint>

    <link name="${name}link5">
      <xacro:default_inertial/>
    </link>
      
    <gazebo reference="${name}link5">
      <material>Gazebo/White</material>
    </gazebo>
      
  <xacro:arm_SimpleTransmission number="1"></xacro:arm_SimpleTransmission>
  <xacro:arm_SimpleTransmission number="2"></xacro:arm_SimpleTransmission>
  <xacro:arm_SimpleTransmission number="3"></xacro:arm_SimpleTransmission>
  <xacro:arm_SimpleTransmission number="4"></xacro:arm_SimpleTransmission>
  <xacro:arm_SimpleTransmission number="5"></xacro:arm_SimpleTransmission>

    <transmission name="${name}base_trans">
      <type>transmission_interface/SimpleTransmission</type>
      <joint name="${name}base_joint">
        <hardwareInterface>PositionJointInterface</hardwareInterface>
      </joint>
      <actuator name="${name}base_motor">
        <mechanicalReduction>1</mechanicalReduction>
      </actuator>
    </transmission>

  </xacro:macro>

  <xacro:macro name="arm_SimpleTransmission" params="number">
    <transmission name="arm_${number}_trans">
      <type>transmission_interface/SimpleTransmission</type>
      <joint name="${name}joint${number}">
        <hardwareInterface>PositionJointInterface</hardwareInterface>
      </joint>
      <actuator name="arm_${number}_motor">
        <mechanicalReduction>1</mechanicalReduction>
      </actuator>
    </transmission>
  </xacro:macro>

  <xacro:macro name="default_inertial">
    <inertial>
      <mass value="0.01"/>
      <origin xyz="0 0 0"/>
      <inertia ixx="0.001" ixy="0.0" ixz="0.0" iyy="0.001" iyz="0.0" izz="0.001" />
    </inertial>
  </xacro:macro>

</robot>
