<?xml version="1.0"?>
<root xmlns:xacro="http://www.ros.org/wiki/xacro">

  <xacro:include filename="$(find robotino_description)/urdf/base.gazebo.xacro" />
  <xacro:include filename="$(find robotino_description)/urdf/base.transmission.xacro" />

  <xacro:macro name="base" params="name">

  <link name="${name}_link" />

   <joint name="${name}_body_joint" type="fixed">
    <parent link="${name}_link"/>
    <child link="${name}_body_link"/>
    <origin xyz="0 0 0" rpy="0 0 0" />
   </joint>

  <link name="${name}_body_link">
    <inertial>
      <mass value="10" />
      <origin xyz="0 0 0" />
      <inertia ixx="75.0" ixy="0.0" ixz="0.0"
       iyy="75.0" iyz="0.0"
       izz="75.0" />
    </inertial>
    <visual>
      <origin xyz="0.01 0 0" rpy="0 0 0"/>
      <geometry>
       <mesh filename="package://robotino_description/meshes/RobotinoBody.dae"/>
      </geometry>
    </visual>
    <collision>
      <origin xyz="0.01 0 0" rpy="0 0 0"/>
      <geometry>
       <mesh filename="package://robotino_description/meshes/RobotinoBody.stl"/>
      </geometry>
    </collision>
   </link>

   <base_gazebo name="base" />

  <gazebo>
    <plugin name="base_controller" filename="libgazebo_ros_planar_move.so">
      <commandTopic>cmd_vel</commandTopic>
      <odometryTopic>odom</odometryTopic>
      <odometryFrame>odom</odometryFrame>
      <odometryRate>20.0</odometryRate>
      <robotBaseFrame>base_link</robotBaseFrame>
    </plugin>
  </gazebo>

   <wheel name="wheel0" parent="base_link">
    <origin xyz="0.095 0.14 0.02" rpy="0 0 ${M_PI/3}"/>
    <axis xyz="-1 0 0"/>
   </wheel>
   <wheel_transmission name="wheel0" />
   <wheel_gazebo name="wheel0" />
   <wheel name="wheel1" parent="base_link">
    <origin xyz="-0.16 0 0.02" rpy="0 0 0"/>
    <axis xyz="1 0 0"/>
   </wheel>
   <wheel_transmission name="wheel1" />
   <wheel_gazebo name="wheel1" />
   <wheel name="wheel2" parent="base_link">
    <origin xyz="0.105 -0.15 0.02" rpy="0 0 -${M_PI/3}"/>
    <axis xyz="-1 0 0"/>
   </wheel>
   <wheel_transmission name="wheel2" />
   <wheel_gazebo name="wheel2" />
  </xacro:macro>

  <!-- WHEEL -->
  <xacro:macro name="wheel" params="parent name *origin *axis">
   <joint name="${name}_joint" type="continuous">
    <parent link="${parent}"/>
    <child link="${name}_link" />
    <insert_block name="origin" />
    <insert_block name="axis" />
   </joint>

   <link name="${name}_link">
    <inertial>
      <mass value="0.4" />
      <origin xyz="0 0 0" />
      <inertia ixx="0.012411765597" ixy="-0.000711733678" ixz="0.00050272983" iyy="0.015218160428" iyz="-0.000004273467" izz="0.011763977943"/>
    </inertial>
    <visual>
      <origin xyz="0 0 0" rpy="0 0 0" />
      <geometry>
       <mesh filename="package://robotino_description/meshes/RobotinoWheel.dae" scale="${M_SCALE} ${M_SCALE} ${M_SCALE}"/>
      </geometry>
    </visual>
    <collision>
      <origin xyz="0 0 0" rpy="0 ${M_PI/2} 0" />
      <geometry>
       <cylinder length="0.04" radius="0.04"/>
      </geometry>
    </collision>
   </link>
  </xacro:macro>

</root>

