<?xml version="1.0"?>
<robot xmlns:xacro="http://www.ros.org/wiki/xacro">

  <xacro:include filename="$(find kclhand_description)/urdf/kclhand.gazebo.xacro" />
  <xacro:include filename="$(find kclhand_description)/urdf/kclhand.transmission.xacro" />

  <xacro:macro name="kclhand" params="parent name *origin">

  <joint name="${name}_wrist_joint" type="fixed">
    <insert_block name="origin" />
    <parent link="${parent}" />
    <child link="${name}_wrist_link" />
    </joint>

  <link name="${name}_wrist_link">
      <xacro:default_inertial/>
    <visual>
      <origin xyz="0 0 0" rpy="0 0 0" />
      <geometry>
        <mesh filename="package://kclhand_description/meshes/wrist.stl" />
      </geometry>
      <material name="">
        <color rgba="0.79216 0.81961 0.93333 1" />
      </material>
    </visual>
    <collision>
      <origin xyz="0 0 0" rpy="0 0 0" />
      <geometry>
        <mesh filename="package://kclhand_description/meshes/wrist.stl" />
      </geometry>
    </collision>
  </link>

  <joint name="${name}_base_joint" type="fixed">
    <origin xyz="-0.02105 0.1485 0" rpy="0 0.52 0" />
    <parent link="${name}_wrist_link" />
    <child link="${name}_base_link" />
    </joint>

  <link name="${name}_base_link">
      <xacro:default_inertial/>
    <visual>
      <origin xyz="0 0 0" rpy="0 0 0" />
      <geometry>
        <mesh filename="package://kclhand_description/meshes/base_link.STL" />
      </geometry>
      <material name="">
        <color rgba="0.79216 0.81961 0.93333 1" />
      </material>
    </visual>
    <collision>
      <origin xyz="0 0 0" rpy="0 0 0" />
      <geometry>
        <mesh filename="package://kclhand_description/meshes/base_link.STL" />
      </geometry>
    </collision>
  </link>

  <joint name="${name}_middle_finger_lower_joint" type="continuous">
    <origin xyz="0.035507 0.02 0.0205" rpy="-0.5236 5.5511E-17 1.5708" />
    <parent link="${name}_base_link" />
    <child link="${name}_middle_finger_lower_link" />
    <axis xyz="0 0 -1" />
  </joint>

  <link name="${name}_middle_finger_lower_link">
      <xacro:default_inertial/>
    <visual>
      	<origin xyz="0 0 0" rpy="0 0 0" />
      <geometry>
        <mesh filename="package://kclhand_description/meshes/middle_finger_lower_link.STL" />
      </geometry>
      <material name="">
        <color rgba="0.79216 0.81961 0.93333 1" />
      </material>
    </visual>
    <collision>
      <origin xyz="0 0 0" rpy="0 0 0" />
      <geometry>
        <mesh filename="package://kclhand_description/meshes/middle_finger_lower_link.STL" />
      </geometry>
    </collision>
  </link>

  <joint name="${name}_middle_finger_upper_joint" type="continuous">
    <origin xyz="0.05 0 0" rpy="0 0 0.7854" />
    <parent link="${name}_middle_finger_lower_link" />
    <child link="${name}_middle_finger_upper_link" />
    <axis xyz="0 0 1" />
  </joint>

  <link name="${name}_middle_finger_upper_link">
      <xacro:default_inertial/>
    <visual>
      <origin xyz="0 0 0" rpy="0 0 0" />
      <geometry>
        <mesh filename="package://kclhand_description/meshes/middle_finger_upper_link.STL" />
      </geometry>
      <material name="">
        <color rgba="0.79216 0.81961 0.93333 1" />
      </material>
    </visual>
    <collision>
      <origin xyz="0 0 0" rpy="0 0 0" />
      <geometry>
        <mesh filename="package://kclhand_description/meshes/middle_finger_upper_link.STL" />
      </geometry>
    </collision>
  </link>

  <joint name="${name}_left_crank_base_joint" type="continuous">
		<origin xyz="0 0 0" rpy="-2.1588 0.44783 -1.8518" />
    <parent link="${name}_base_link" />
    <child link="${name}_left_crank" />
    <axis xyz="0 0 1" />
  </joint>

  <link name="${name}_left_crank">
      <xacro:default_inertial/>
    <visual>
      <origin xyz="0 0 0" rpy="0 0 0" />
      <geometry>
        <mesh filename="package://kclhand_description/meshes/left_crank.STL" />
      </geometry>
      <material name="">
        <color rgba="0.79216 0.81961 0.93333 1" />
      </material>
    </visual>
    <collision>
      <origin xyz="0 0 0" rpy="0 0 0" />
      <geometry>
        <mesh filename="package://kclhand_description/meshes/left_crank.STL" />
      </geometry>
    </collision>
  </link>

  <joint name="${name}_left_coupler_crank_joint" type="continuous">
    <origin xyz="0 0 0" rpy="0.40154 0.63113 0.62376" />
    <parent link="${name}_left_crank" />
    <child link="${name}_left_coupler" />
    <axis xyz="0 0 1" />
  </joint>

  <link name="${name}_left_coupler">
      <xacro:default_inertial/>
    <visual>
      <origin xyz="0 0 0" rpy="0 0 0" />
      <geometry>
        <mesh
          filename="package://kclhand_description/meshes/left_coupler.STL" />
      </geometry>
      <material name="">
        <color rgba="0.79216 0.81961 0.93333 1" />
      </material>
    </visual>
    <collision>
      <origin xyz="0 0 0" rpy="0 0 0" />
      <geometry>
        <mesh filename="package://kclhand_description/meshes/left_coupler.STL" />
      </geometry>
    </collision>
  </link>

  <joint name="${name}_left_finger_lower_joint" type="continuous">
    <origin xyz="0.016246 0.021 0.044635" rpy="-1.2217 -7.6328E-17 1.5708" />
    <parent link="${name}_left_coupler" />
    <child link="${name}_left_finger_lower_link" />
    <axis xyz="0 0 -1" />
  </joint>

  <link name="${name}_left_finger_lower_link">
      <xacro:default_inertial/>
    <visual>
      <origin xyz="0 0 0" rpy="0 0 0" />
      <geometry>
        <mesh filename="package://kclhand_description/meshes/left_finger_lower_link.STL" />
      </geometry>
      <material name="">
        <color rgba="0.79216 0.81961 0.93333 1" />
      </material>
    </visual>
    <collision>
      <origin xyz="0 0 0" rpy="0 0 0" />
      <geometry>
        <mesh filename="package://kclhand_description/meshes/left_finger_lower_link.STL" />
      </geometry>
    </collision>
  </link>

  <joint name="${name}_left_finger_upper_joint" type="continuous">
    <origin xyz="0.05 0 0" rpy="-1.5543E-15 7.7716E-16 0.7854" />
    <parent link="${name}_left_finger_lower_link" />
    <child link="${name}_left_finger_upper_link" />
    <axis xyz="0 0 1" />
  </joint>

  <link name="${name}_left_finger_upper_link">
      <xacro:default_inertial/>
    <visual>
      <origin xyz="0 0 0" rpy="0 0 0" />
      <geometry>
        <mesh filename="package://kclhand_description/meshes/left_finger_upper_link.STL" />
      </geometry>
      <material name="">
        <color rgba="0.79216 0.81961 0.93333 1" />
      </material>
    </visual>
    <collision>
      <origin xyz="0 0 0" rpy="0 0 0" />
      <geometry>
        <mesh filename="package://kclhand_description/meshes/left_finger_upper_link.STL" />
      </geometry>
    </collision>
  </link>

  <joint name="${name}_right_crank_base_joint" type="continuous">
    <origin xyz="0 0 0" rpy="-5.5511E-17 -2.7756E-17 1.0472" />
    <parent link="${name}_base_link" />
    <child link="${name}_right_crank" />
    <axis xyz="0 0 1" />
  </joint>

  <link name="${name}_right_crank">
      <xacro:default_inertial/>
    <visual>
      <origin xyz="0 0 0" rpy="0 0 0" />
      <geometry>
        <mesh filename="package://kclhand_description/meshes/right_crank.STL" />
      </geometry>
      <material name="">
        <color rgba="0.79216 0.81961 0.93333 1" />
      </material>
    </visual>
    <collision>
      <origin xyz="0 0 0" rpy="0 0 0" />
      <geometry>
        <mesh filename="package://kclhand_description/meshes/right_crank.STL" />
      </geometry>
    </collision>
  </link>

  <joint name="${name}_right_coupler_crank_joint" type="continuous">
    <origin xyz="0 0 0" rpy="0.40154 -0.63113 -0.62376" />
    <parent link="${name}_right_crank" />
    <child link="${name}_right_coupler" />
    <axis xyz="0 0 1" />
  </joint>

  <link name="${name}_right_coupler">
      <xacro:default_inertial/>
    <visual>
      <origin xyz="0 0 0" rpy="0 0 0" />
      <geometry>
        <mesh filename="package://kclhand_description/meshes/right_coupler.STL" />
      </geometry>
      <material name="">
        <color rgba="0.79216 0.81961 0.93333 1" />
      </material>
    </visual>
    <collision>
      <origin xyz="0 0 0" rpy="0 0 0" />
      <geometry>
        <mesh filename="package://kclhand_description/meshes/right_coupler.STL" />
      </geometry>
    </collision>
  </link>

  <joint name="${name}_right_finger_lower_joint" type="continuous">
    <origin xyz="-0.016246 0.021 0.044635" rpy="-1.9199 -2.047E-16 1.5708" />
    <parent link="${name}_right_coupler" />
    <child link="${name}_right_finger_lower_link" />
    <axis xyz="0 0 1" />
  </joint>

  <link name="${name}_right_finger_lower_link">
      <xacro:default_inertial/>
    <visual>
      <origin xyz="0 0 0" rpy="0 0 0" />
      <geometry>
        <mesh filename="package://kclhand_description/meshes/right_finger_lower_link.STL" />
      </geometry>
      <material name="">
        <color rgba="0.79216 0.81961 0.93333 1" />
      </material>
    </visual>
    <collision>
      <origin xyz="0 0 0" rpy="0 0 0" />
      <geometry>
        <mesh filename="package://kclhand_description/meshes/right_finger_lower_link.STL" />
      </geometry>
    </collision>
  </link>

  <joint name="${name}_right_finger_upper_joint" type="continuous">
    <origin xyz="0.05 0 0" rpy="4.4409E-16 -2.9143E-16 0.7854" />
    <parent link="${name}_right_finger_lower_link" />
    <child link="${name}_right_finger_upper_link" />
    <axis xyz="0 0 1" />
  </joint>

  <link name="${name}_right_finger_upper_link">
      <xacro:default_inertial/>
    <visual>
      <origin xyz="0 0 0" rpy="0 0 0" />
      <geometry>
        <mesh filename="package://kclhand_description/meshes/right_finger_upper_link.STL" />
      </geometry>
      <material  name="">
        <color rgba="0.792156862745098 0.819607843137255 0.933333333333333 1" />
      </material>
    </visual>
    <collision>
      <origin xyz="0 0 0" rpy="0 0 0" />
      <geometry>
        <mesh filename="package://kclhand_description/meshes/right_finger_upper_link.STL" />
      </geometry>
    </collision>
  </link>

  <joint name="${name}_cableCanal_joint" type="fixed">
    <origin xyz="0 0.06 0.07" rpy="0 0 0" />
    <parent link="${name}_wrist_link" />
    <child link="${name}_cableCanal_link" />
  </joint>

  <link name="${name}_cableCanal_link">
      <xacro:default_inertial/>
    <visual>
      <origin xyz="0 0 0" rpy="0 0 0" />
      <geometry>
        <box size="0.0 0.0 0.0" />
      </geometry>
      <material name="">
        <color rgba="0.79216 0.81961 0.93333 1" />
      </material>
    </visual>
    <collision>
      <origin xyz="0 0 0" rpy="0 0 0" />
      <geometry>
        <mesh filename="package://kclhand_description/meshes/cableCanalCollision.stl" />
      </geometry>
    </collision>
  </link>
    <xacro:kclhand_transmission name="hand" />
    <xacro:kclhand_gazebo name="hand" />

 </xacro:macro>

  <xacro:macro name="default_inertial">
    <inertial>
      <mass value="0.01"/>
      <origin xyz="0 0 0"/>
      <inertia ixx="0.001" ixy="0.0" ixz="0.0" iyy="0.001" iyz="0.0" izz="0.001" />
    </inertial>
  </xacro:macro>
</robot>
